2018-07-09 11:32:40,553 ERROR: Exception on / [GET] [in c:\pythonfiles\resume_website\venv\lib\site-packages\flask\app.py:1761]
Traceback (most recent call last):
  File "c:\pythonfiles\resume_website\venv\lib\site-packages\flask\app.py", line 2292, in wsgi_app
    response = self.full_dispatch_request()
  File "c:\pythonfiles\resume_website\venv\lib\site-packages\flask\app.py", line 1815, in full_dispatch_request
    rv = self.handle_user_exception(e)
  File "c:\pythonfiles\resume_website\venv\lib\site-packages\flask\app.py", line 1718, in handle_user_exception
    reraise(exc_type, exc_value, tb)
  File "c:\pythonfiles\resume_website\venv\lib\site-packages\flask\_compat.py", line 35, in reraise
    raise value
  File "c:\pythonfiles\resume_website\venv\lib\site-packages\flask\app.py", line 1813, in full_dispatch_request
    rv = self.dispatch_request()
  File "c:\pythonfiles\resume_website\venv\lib\site-packages\flask\app.py", line 1799, in dispatch_request
    return self.view_functions[rule.endpoint](**req.view_args)
  File "C:\Pythonfiles\resume_website\app\routes.py", line 13, in index
    return render_template('index2.html', form=form)
  File "c:\pythonfiles\resume_website\venv\lib\site-packages\flask\templating.py", line 135, in render_template
    context, ctx.app)
  File "c:\pythonfiles\resume_website\venv\lib\site-packages\flask\templating.py", line 117, in _render
    rv = template.render(context)
  File "c:\pythonfiles\resume_website\venv\lib\site-packages\jinja2\asyncsupport.py", line 76, in render
    return original_render(self, *args, **kwargs)
  File "c:\pythonfiles\resume_website\venv\lib\site-packages\jinja2\environment.py", line 1008, in render
    return self.environment.handle_exception(exc_info, True)
  File "c:\pythonfiles\resume_website\venv\lib\site-packages\jinja2\environment.py", line 780, in handle_exception
    reraise(exc_type, exc_value, tb)
  File "c:\pythonfiles\resume_website\venv\lib\site-packages\jinja2\_compat.py", line 37, in reraise
    raise value.with_traceback(tb)
  File "C:\Pythonfiles\resume_website\app\templates\index2.html", line 356, in top-level template code
    {% block content %}
  File "C:\Pythonfiles\resume_website\app\templates\index2.html", line 362, in block "content"
    <p>{{ form.hidden_tag() }}</p>
TypeError: hidden_tag() missing 1 required positional argument: 'self'
2018-07-09 11:33:17,437 INFO: Website startup [in C:\Pythonfiles\resume_website\app\__init__.py:45]
2018-07-09 11:33:21,497 ERROR: Exception on / [GET] [in c:\pythonfiles\resume_website\venv\lib\site-packages\flask\app.py:1761]
Traceback (most recent call last):
  File "c:\pythonfiles\resume_website\venv\lib\site-packages\flask\app.py", line 2292, in wsgi_app
    response = self.full_dispatch_request()
  File "c:\pythonfiles\resume_website\venv\lib\site-packages\flask\app.py", line 1815, in full_dispatch_request
    rv = self.handle_user_exception(e)
  File "c:\pythonfiles\resume_website\venv\lib\site-packages\flask\app.py", line 1718, in handle_user_exception
    reraise(exc_type, exc_value, tb)
  File "c:\pythonfiles\resume_website\venv\lib\site-packages\flask\_compat.py", line 35, in reraise
    raise value
  File "c:\pythonfiles\resume_website\venv\lib\site-packages\flask\app.py", line 1813, in full_dispatch_request
    rv = self.dispatch_request()
  File "c:\pythonfiles\resume_website\venv\lib\site-packages\flask\app.py", line 1799, in dispatch_request
    return self.view_functions[rule.endpoint](**req.view_args)
  File "C:\Pythonfiles\resume_website\app\routes.py", line 13, in index
    return render_template('index2.html', form=form)
  File "c:\pythonfiles\resume_website\venv\lib\site-packages\flask\templating.py", line 135, in render_template
    context, ctx.app)
  File "c:\pythonfiles\resume_website\venv\lib\site-packages\flask\templating.py", line 117, in _render
    rv = template.render(context)
  File "c:\pythonfiles\resume_website\venv\lib\site-packages\jinja2\asyncsupport.py", line 76, in render
    return original_render(self, *args, **kwargs)
  File "c:\pythonfiles\resume_website\venv\lib\site-packages\jinja2\environment.py", line 1008, in render
    return self.environment.handle_exception(exc_info, True)
  File "c:\pythonfiles\resume_website\venv\lib\site-packages\jinja2\environment.py", line 780, in handle_exception
    reraise(exc_type, exc_value, tb)
  File "c:\pythonfiles\resume_website\venv\lib\site-packages\jinja2\_compat.py", line 37, in reraise
    raise value.with_traceback(tb)
  File "C:\Pythonfiles\resume_website\app\templates\index2.html", line 356, in top-level template code
    {% block content %}
  File "C:\Pythonfiles\resume_website\app\templates\index2.html", line 362, in block "content"
    <p>{{ form.hidden_tag() }}</p>
TypeError: hidden_tag() missing 1 required positional argument: 'self'
2018-07-09 11:34:06,803 INFO: Website startup [in C:\Pythonfiles\resume_website\app\__init__.py:45]
2018-07-09 11:34:10,337 ERROR: Exception on / [GET] [in c:\pythonfiles\resume_website\venv\lib\site-packages\flask\app.py:1761]
Traceback (most recent call last):
  File "c:\pythonfiles\resume_website\venv\lib\site-packages\flask\app.py", line 2292, in wsgi_app
    response = self.full_dispatch_request()
  File "c:\pythonfiles\resume_website\venv\lib\site-packages\flask\app.py", line 1815, in full_dispatch_request
    rv = self.handle_user_exception(e)
  File "c:\pythonfiles\resume_website\venv\lib\site-packages\flask\app.py", line 1718, in handle_user_exception
    reraise(exc_type, exc_value, tb)
  File "c:\pythonfiles\resume_website\venv\lib\site-packages\flask\_compat.py", line 35, in reraise
    raise value
  File "c:\pythonfiles\resume_website\venv\lib\site-packages\flask\app.py", line 1813, in full_dispatch_request
    rv = self.dispatch_request()
  File "c:\pythonfiles\resume_website\venv\lib\site-packages\flask\app.py", line 1799, in dispatch_request
    return self.view_functions[rule.endpoint](**req.view_args)
  File "C:\Pythonfiles\resume_website\app\routes.py", line 13, in index
    return render_template('index2.html', form=form)
  File "c:\pythonfiles\resume_website\venv\lib\site-packages\flask\templating.py", line 135, in render_template
    context, ctx.app)
  File "c:\pythonfiles\resume_website\venv\lib\site-packages\flask\templating.py", line 117, in _render
    rv = template.render(context)
  File "c:\pythonfiles\resume_website\venv\lib\site-packages\jinja2\asyncsupport.py", line 76, in render
    return original_render(self, *args, **kwargs)
  File "c:\pythonfiles\resume_website\venv\lib\site-packages\jinja2\environment.py", line 1008, in render
    return self.environment.handle_exception(exc_info, True)
  File "c:\pythonfiles\resume_website\venv\lib\site-packages\jinja2\environment.py", line 780, in handle_exception
    reraise(exc_type, exc_value, tb)
  File "c:\pythonfiles\resume_website\venv\lib\site-packages\jinja2\_compat.py", line 37, in reraise
    raise value.with_traceback(tb)
  File "C:\Pythonfiles\resume_website\app\templates\index2.html", line 356, in top-level template code
    {% block content %}
  File "C:\Pythonfiles\resume_website\app\templates\index2.html", line 376, in block "content"
    <p>{{ form.submit() }}</p>
TypeError: 'UnboundField' object is not callable
2018-07-09 11:34:14,659 ERROR: Exception on / [GET] [in c:\pythonfiles\resume_website\venv\lib\site-packages\flask\app.py:1761]
Traceback (most recent call last):
  File "c:\pythonfiles\resume_website\venv\lib\site-packages\flask\app.py", line 2292, in wsgi_app
    response = self.full_dispatch_request()
  File "c:\pythonfiles\resume_website\venv\lib\site-packages\flask\app.py", line 1815, in full_dispatch_request
    rv = self.handle_user_exception(e)
  File "c:\pythonfiles\resume_website\venv\lib\site-packages\flask\app.py", line 1718, in handle_user_exception
    reraise(exc_type, exc_value, tb)
  File "c:\pythonfiles\resume_website\venv\lib\site-packages\flask\_compat.py", line 35, in reraise
    raise value
  File "c:\pythonfiles\resume_website\venv\lib\site-packages\flask\app.py", line 1813, in full_dispatch_request
    rv = self.dispatch_request()
  File "c:\pythonfiles\resume_website\venv\lib\site-packages\flask\app.py", line 1799, in dispatch_request
    return self.view_functions[rule.endpoint](**req.view_args)
  File "C:\Pythonfiles\resume_website\app\routes.py", line 13, in index
    return render_template('index2.html', form=form)
  File "c:\pythonfiles\resume_website\venv\lib\site-packages\flask\templating.py", line 135, in render_template
    context, ctx.app)
  File "c:\pythonfiles\resume_website\venv\lib\site-packages\flask\templating.py", line 117, in _render
    rv = template.render(context)
  File "c:\pythonfiles\resume_website\venv\lib\site-packages\jinja2\asyncsupport.py", line 76, in render
    return original_render(self, *args, **kwargs)
  File "c:\pythonfiles\resume_website\venv\lib\site-packages\jinja2\environment.py", line 1008, in render
    return self.environment.handle_exception(exc_info, True)
  File "c:\pythonfiles\resume_website\venv\lib\site-packages\jinja2\environment.py", line 780, in handle_exception
    reraise(exc_type, exc_value, tb)
  File "c:\pythonfiles\resume_website\venv\lib\site-packages\jinja2\_compat.py", line 37, in reraise
    raise value.with_traceback(tb)
  File "C:\Pythonfiles\resume_website\app\templates\index2.html", line 356, in top-level template code
    {% block content %}
  File "C:\Pythonfiles\resume_website\app\templates\index2.html", line 376, in block "content"
    <p>{{ form.submit() }}</p>
TypeError: 'UnboundField' object is not callable
2018-07-09 11:36:59,010 INFO: Website startup [in C:\Pythonfiles\resume_website\app\__init__.py:45]
2018-07-09 11:39:38,927 INFO: Website startup [in C:\Pythonfiles\resume_website\app\__init__.py:45]
2018-07-09 11:40:30,209 INFO: Website startup [in C:\Pythonfiles\resume_website\app\__init__.py:45]
2018-07-09 11:46:13,990 INFO: Website startup [in C:\Pythonfiles\resume_website\app\__init__.py:45]
